<?xml version="1.0" ?>
<!-- =================================================================================== -->
<!-- |    This document was autogenerated by xacro from /home/carson/ros2_ws/src/gentact_descriptions/robots/h1-2/h1_2_handless.urdf.xacro | -->
<!-- |    EDITING THIS FILE BY HAND IS NOT RECOMMENDED                                 | -->
<!-- =================================================================================== -->
<robot name="h1_2">
  <mujoco>
    <compiler discardvisual="false" meshdir="meshes"/>
  </mujoco>
  <!-- [CAUTION] uncomment when convert to mujoco -->
  <!-- <link name="world"></link>
  <joint name="floating_base_joint" type="floating">
    <parent link="world"/>
    <child link="pelvis"/>
  </joint> -->
  <link name="pelvis">
    <inertial>
      <origin rpy="0 0 0" xyz="-0.0004 3.7E-05 -0.046864"/>
      <mass value="5.983"/>
      <inertia ixx="49168.411E-06" ixy="-19.869E-06" ixz="-48.460E-06" iyy="9025.844E-06" iyz="3.431E-06" izz="53155.891E-06"/>
    </inertial>
    <visual>
      <origin rpy="0 0 0" xyz="0 0 0"/>
      <geometry>
        <mesh filename="meshes/pelvis.STL"/>
      </geometry>
      <material>
        <color rgba="0.1 0.1 0.1 1"/>
      </material>
    </visual>
    <collision>
      <origin rpy="0 0 0" xyz="0 0 0"/>
      <geometry>
        <mesh filename="meshes/pelvis.STL"/>
      </geometry>
    </collision>
  </link>
  <!-- L Leg -->
  <link name="left_hip_yaw_link">
    <inertial>
      <origin rpy="0 0 0" xyz="0 -0.026197 0.006647"/>
      <mass value="2.829"/>
      <inertia ixx="4553.605E-06" ixy="0.005E-06" ixz="0.817E-06" iyy="5688.730E-06" iyz="-345.157E-06" izz="3548.907E-06"/>
    </inertial>
    <visual>
      <origin rpy="0 0 0" xyz="0 0 0"/>
      <geometry>
        <mesh filename="meshes/left_hip_yaw_link.STL"/>
      </geometry>
      <material>
        <color rgba="0.1 0.1 0.1 1"/>
      </material>
    </visual>
  </link>
  <joint name="left_hip_yaw_joint" type="revolute">
    <origin rpy="0 0 0" xyz="0 0.0875 -0.1632"/>
    <parent link="pelvis"/>
    <child link="left_hip_yaw_link"/>
    <axis xyz="0 0 1"/>
    <limit effort="200" lower="-0.43" upper="0.43" velocity="23"/>
  </joint>
  <link name="left_hip_pitch_link">
    <inertial>
      <origin rpy="0 0 0" xyz="-0.00781 -0.004724 -0.000063"/>
      <mass value="2.920"/>
      <inertia ixx="5594.7E-06" ixy="143.308E-06" ixz="-11.847E-06" iyy="3862.581E-06" iyz="-9.607E-06" izz="4450.563E-06"/>
    </inertial>
    <visual>
      <origin rpy="0 0 0" xyz="0 0 0"/>
      <geometry>
        <mesh filename="meshes/left_hip_pitch_link.STL"/>
      </geometry>
      <material>
        <color rgba="0.1 0.1 0.1 1"/>
      </material>
    </visual>
    <collision>
      <origin rpy="0 0 0" xyz="0 0 0"/>
      <geometry>
        <mesh filename="meshes/left_hip_pitch_link.STL"/>
      </geometry>
    </collision>
  </link>
  <joint name="left_hip_pitch_joint" type="revolute">
    <origin rpy="0 0 0" xyz="0 0.0755 0"/>
    <parent link="left_hip_yaw_link"/>
    <child link="left_hip_pitch_link"/>
    <axis xyz="0 1 0"/>
    <limit effort="200" lower="-3.14" upper="2.5" velocity="23"/>
  </joint>
  <link name="left_hip_roll_link">
    <inertial>
      <origin rpy="0 0 0" xyz="0.004171 -0.008576 -0.194509"/>
      <mass value="4.962"/>
      <inertia ixx="46305.869E-06" ixy="-322.626E-06" ixz="-1199.703E-06" iyy="47955.402E-06" iyz="288.147E-06" izz="8914.518E-06"/>
    </inertial>
    <visual>
      <origin rpy="0 0 0" xyz="0 0 0"/>
      <geometry>
        <mesh filename="meshes/left_hip_roll_link.STL"/>
      </geometry>
      <material>
        <color rgba="0.1 0.1 0.1 1"/>
      </material>
    </visual>
    <collision>
      <origin rpy="0 0 0" xyz="0 0 0"/>
      <geometry>
        <mesh filename="meshes/left_hip_roll_link.STL"/>
      </geometry>
    </collision>
  </link>
  <joint name="left_hip_roll_joint" type="revolute">
    <origin rpy="0 0 0" xyz="0 0 0"/>
    <parent link="left_hip_pitch_link"/>
    <child link="left_hip_roll_link"/>
    <axis xyz="1 0 0"/>
    <limit effort="200" lower="-0.43" upper="3.14" velocity="23"/>
  </joint>
  <link name="left_knee_link">
    <inertial>
      <origin rpy="0 0 0" xyz="0.000179 0.000121 -0.168936"/>
      <mass value="3.839"/>
      <inertia ixx="39002.363e-6" ixy="-72.364e-6" ixz="-794.506e-6" iyy="39042.376e-6" iyz="-18.663e-6" izz="5029.829e-6"/>
    </inertial>
    <visual>
      <origin rpy="0 0 0" xyz="0 0 0"/>
      <geometry>
        <mesh filename="meshes/left_knee_link.STL"/>
      </geometry>
      <material>
        <color rgba="0.1 0.1 0.1 1"/>
      </material>
    </visual>
    <collision>
      <origin rpy="0 0 0" xyz="0 0 -0.2"/>
      <geometry>
        <cylinder length="0.2" radius="0.04"/>
      </geometry>
    </collision>
  </link>
  <joint name="left_knee_joint" type="revolute">
    <origin rpy="0 0 0" xyz="0 0 -0.4"/>
    <parent link="left_hip_roll_link"/>
    <child link="left_knee_link"/>
    <axis xyz="0 1 0"/>
    <limit effort="300" lower="-0.12" upper="2.19" velocity="14"/>
  </joint>
  <link name="left_ankle_pitch_link">
    <inertial>
      <origin rpy="0 0 0" xyz="-0.000294 0 -0.010794"/>
      <mass value="0.102"/>
      <inertia ixx="0.000023944" ixy="0" ixz="0.000000121" iyy="0.000021837" iyz="0" izz="0.000013414"/>
    </inertial>
    <visual>
      <origin rpy="0 0 0" xyz="0 0 0"/>
      <geometry>
        <mesh filename="meshes/left_ankle_pitch_link.STL"/>
      </geometry>
      <material>
        <color rgba="0.1 0.1 0.1 1"/>
      </material>
    </visual>
  </link>
  <joint name="left_ankle_pitch_joint" type="revolute">
    <origin rpy="0 0 0" xyz="0 0 -0.4"/>
    <parent link="left_knee_link"/>
    <child link="left_ankle_pitch_link"/>
    <axis xyz="0 1 0"/>
    <limit effort="60" lower="-0.897334" upper="0.523598" velocity="9"/>
  </joint>
  <link name="left_ankle_roll_link">
    <inertial>
      <origin rpy="0 0 0" xyz="0.029589 0 -0.015973"/>
      <mass value="0.747"/>
      <inertia ixx="648.830e-6" ixy="0" ixz="158.380e-6" iyy="3435.339e-6" iyz="0" izz="3583.259e-6"/>
    </inertial>
    <visual>
      <origin rpy="0 0 0" xyz="0 0 0"/>
      <geometry>
        <mesh filename="meshes/left_ankle_roll_link.STL"/>
      </geometry>
      <material>
        <color rgba="0.1 0.1 0.1 1"/>
      </material>
    </visual>
    <collision>
      <origin rpy="0 0 0" xyz="0 0 0"/>
      <geometry>
        <mesh filename="meshes/left_ankle_roll_link.STL"/>
      </geometry>
    </collision>
  </link>
  <joint name="left_ankle_roll_joint" type="revolute">
    <origin rpy="0 0 0" xyz="0 0 -0.02"/>
    <parent link="left_ankle_pitch_link"/>
    <child link="left_ankle_roll_link"/>
    <axis xyz="1 0 0"/>
    <limit effort="40" lower="-0.261799" upper="0.261799" velocity="9"/>
  </joint>
  <!-- R Leg -->
  <link name="right_hip_yaw_link">
    <inertial>
      <origin rpy="0 0 0" xyz="0 0.026197 0.006647"/>
      <mass value="2.829"/>
      <inertia ixx="4553.605E-06" ixy="-0.005E-06" ixz="0.817E-06" iyy="5688.730E-06" iyz="345.157E-06" izz="3548.907E-06"/>
    </inertial>
    <visual>
      <origin rpy="0 0 0" xyz="0 0 0"/>
      <geometry>
        <mesh filename="meshes/right_hip_yaw_link.STL"/>
      </geometry>
      <material>
        <color rgba="0.1 0.1 0.1 1"/>
      </material>
    </visual>
  </link>
  <joint name="right_hip_yaw_joint" type="revolute">
    <origin rpy="0 0 0" xyz="0 -0.0875 -0.1632"/>
    <parent link="pelvis"/>
    <child link="right_hip_yaw_link"/>
    <axis xyz="0 0 1"/>
    <limit effort="200" lower="-0.43" upper="0.43" velocity="23"/>
  </joint>
  <link name="right_hip_pitch_link">
    <inertial>
      <origin rpy="0 0 0" xyz="-0.00781 0.004724 -0.000063"/>
      <mass value="2.920"/>
      <inertia ixx="5594.7E-06" ixy="-143.308E-06" ixz="-11.847E-06" iyy="3862.581E-06" iyz="9.607E-06" izz="4450.563E-06"/>
    </inertial>
    <visual>
      <origin rpy="0 0 0" xyz="0 0 0"/>
      <geometry>
        <mesh filename="meshes/right_hip_pitch_link.STL"/>
      </geometry>
      <material>
        <color rgba="0.1 0.1 0.1 1"/>
      </material>
    </visual>
    <collision>
      <origin rpy="0 0 0" xyz="0 0 0"/>
      <geometry>
        <mesh filename="meshes/right_hip_pitch_link.STL"/>
      </geometry>
    </collision>
  </link>
  <joint name="right_hip_pitch_joint" type="revolute">
    <origin rpy="0 0 0" xyz="0 -0.0755 0"/>
    <parent link="right_hip_yaw_link"/>
    <child link="right_hip_pitch_link"/>
    <axis xyz="0 1 0"/>
    <limit effort="200" lower="-3.14" upper="2.5" velocity="23"/>
  </joint>
  <link name="right_hip_roll_link">
    <inertial>
      <origin rpy="0 0 0" xyz="0.004171 0.008576 -0.194509"/>
      <mass value="4.962"/>
      <inertia ixx="46305.869E-06" ixy="322.626E-06" ixz="-1199.703E-06" iyy="47955.402E-06" iyz="-288.147E-06" izz="8914.518E-06"/>
    </inertial>
    <visual>
      <origin rpy="0 0 0" xyz="0 0 0"/>
      <geometry>
        <mesh filename="meshes/right_hip_roll_link.STL"/>
      </geometry>
      <material>
        <color rgba="0.1 0.1 0.1 1"/>
      </material>
    </visual>
    <collision>
      <origin rpy="0 0 0" xyz="0 0 0"/>
      <geometry>
        <mesh filename="meshes/right_hip_roll_link.STL"/>
      </geometry>
    </collision>
  </link>
  <joint name="right_hip_roll_joint" type="revolute">
    <origin rpy="0 0 0" xyz="0 0 0"/>
    <parent link="right_hip_pitch_link"/>
    <child link="right_hip_roll_link"/>
    <axis xyz="1 0 0"/>
    <limit effort="200" lower="-3.14" upper="0.43" velocity="23"/>
  </joint>
  <link name="right_knee_link">
    <inertial>
      <origin rpy="0 0 0" xyz="0.000179 -0.000121 -0.168936"/>
      <mass value="3.839"/>
      <inertia ixx="39002.363e-6" ixy="72.364e-6" ixz="-794.506e-6" iyy="39042.376e-6" iyz="18.663e-6" izz="5029.829e-6"/>
    </inertial>
    <visual>
      <origin rpy="0 0 0" xyz="0 0 0"/>
      <geometry>
        <mesh filename="meshes/right_knee_link.STL"/>
      </geometry>
      <material>
        <color rgba="0.1 0.1 0.1 1"/>
      </material>
    </visual>
    <collision>
      <origin rpy="0 0 0" xyz="0 0 -0.2"/>
      <geometry>
        <cylinder length="0.2" radius="0.04"/>
      </geometry>
    </collision>
  </link>
  <joint name="right_knee_joint" type="revolute">
    <origin rpy="0 0 0" xyz="0 0 -0.4"/>
    <parent link="right_hip_roll_link"/>
    <child link="right_knee_link"/>
    <axis xyz="0 1 0"/>
    <limit effort="300" lower="-0.12" upper="2.19" velocity="14"/>
  </joint>
  <link name="right_ankle_pitch_link">
    <inertial>
      <origin rpy="0 0 0" xyz="-0.000294 0 -0.010794"/>
      <mass value="0.102"/>
      <inertia ixx="0.000023944" ixy="0" ixz="0.000000121" iyy="0.000021837" iyz="0" izz="0.000013414"/>
    </inertial>
    <visual>
      <origin rpy="0 0 0" xyz="0 0 0"/>
      <geometry>
        <mesh filename="meshes/right_ankle_pitch_link.STL"/>
      </geometry>
      <material>
        <color rgba="0.1 0.1 0.1 1"/>
      </material>
    </visual>
  </link>
  <joint name="right_ankle_pitch_joint" type="revolute">
    <origin rpy="0 0 0" xyz="0 0 -0.4"/>
    <parent link="right_knee_link"/>
    <child link="right_ankle_pitch_link"/>
    <axis xyz="0 1 0"/>
    <limit effort="60" lower="-0.897334" upper="0.523598" velocity="9"/>
  </joint>
  <link name="right_ankle_roll_link">
    <inertial>
      <origin rpy="0 0 0" xyz="0.029589 0 -0.015973"/>
      <mass value="0.747"/>
      <inertia ixx="648.830e-6" ixy="0" ixz="158.380e-6" iyy="3435.339e-6" iyz="0" izz="3583.259e-6"/>
    </inertial>
    <visual>
      <origin rpy="0 0 0" xyz="0 0 0"/>
      <geometry>
        <mesh filename="meshes/right_ankle_roll_link.STL"/>
      </geometry>
      <material>
        <color rgba="0.1 0.1 0.1 1"/>
      </material>
    </visual>
    <collision>
      <origin rpy="0 0 0" xyz="0 0 0"/>
      <geometry>
        <mesh filename="meshes/right_ankle_roll_link.STL"/>
      </geometry>
    </collision>
  </link>
  <joint name="right_ankle_roll_joint" type="revolute">
    <origin rpy="0 0 0" xyz="0 0 -0.02"/>
    <parent link="right_ankle_pitch_link"/>
    <child link="right_ankle_roll_link"/>
    <axis xyz="1 0 0"/>
    <limit effort="40" lower="-0.261799" upper="0.261799" velocity="9"/>
  </joint>
  <!-- Torso -->
  <link name="torso_link">
    <inertial>
      <origin rpy="0 0 0" xyz="0.000489 0.002797 0.20484"/>
      <mass value="17.789"/>
      <inertia ixx="0.4873" ixy="-0.00053763" ixz="0.0020276" iyy="0.40963" iyz="-0.00074582" izz="0.12785"/>
    </inertial>
    <visual>
      <origin rpy="0 0 0" xyz="0 0 0"/>
      <geometry>
        <mesh filename="meshes/torso_link.STL"/>
      </geometry>
      <material>
        <color rgba="0.1 0.1 0.1 1"/>
      </material>
    </visual>
    <collision>
      <origin rpy="0 0 0" xyz="0 0 0"/>
      <geometry>
        <mesh filename="meshes/torso_link.STL"/>
      </geometry>
    </collision>
  </link>
  <joint name="torso_joint" type="revolute">
    <origin rpy="0 0 0" xyz="0 0 0"/>
    <parent link="pelvis"/>
    <child link="torso_link"/>
    <axis xyz="0 0 1"/>
    <limit effort="200" lower="-2.35" upper="2.35" velocity="23"/>
  </joint>
  <!-- [m] -->
  <link name="torso_skin">
    <visual>
      <origin rpy="0 0 0" xyz="0 0 0"/>
      <geometry>
        <mesh filename="meshes/skin/torso_skin.stl" scale="1 1 1"/>
      </geometry>
    </visual>
  </link>
  <joint name="torso_base_joint" type="fixed">
    <origin rpy="0 0 0" xyz="0 0 0"/>
    <parent link="torso_link"/>
    <child link="torso_skin"/>
  </joint>
  <joint name="torso_sensor_0_joint" type="fixed">
    <origin rpy="1.5707963705062866 -0.0 -1.5707963705062866" xyz="-0.08299999684095383 0.06530754268169403 0.19202354550361633"/>
    <axis xyz="-1.0 0.0 0.0"/>
    <parent link="torso_skin"/>
    <child link="torso_sensor_0"/>
  </joint>
  <link name="torso_sensor_0">
  </link>
  <joint name="torso_sensor_1_joint" type="fixed">
    <origin rpy="1.5707963705062866 -0.0 1.5707963705062866" xyz="0.08300000429153442 -0.018718957901000977 0.23628799617290497"/>
    <axis xyz="1.0 0.0 0.0"/>
    <parent link="torso_skin"/>
    <child link="torso_sensor_1"/>
  </joint>
  <link name="torso_sensor_1">
  </link>
  <joint name="torso_sensor_2_joint" type="fixed">
    <origin rpy="1.569597601890564 7.145217750803567e-11 1.5707964897155762" xyz="0.08291452378034592 0.03239030763506889 0.3974241614341736"/>
    <axis xyz="0.9999992847442627 0.0 0.0011987807229161263"/>
    <parent link="torso_skin"/>
    <child link="torso_sensor_2"/>
  </joint>
  <link name="torso_sensor_2">
  </link>
  <joint name="torso_sensor_3_joint" type="fixed">
    <origin rpy="1.5707963705062866 -0.0 -1.5707963705062866" xyz="-0.08299999684095383 -0.0133847426623106 0.3162384629249573"/>
    <axis xyz="-1.0 0.0 0.0"/>
    <parent link="torso_skin"/>
    <child link="torso_sensor_3"/>
  </joint>
  <link name="torso_sensor_3">
  </link>
  <joint name="torso_sensor_4_joint" type="fixed">
    <origin rpy="1.5707963705062866 -0.0 1.5707963705062866" xyz="0.08300000429153442 0.059501346200704575 0.19160500168800354"/>
    <axis xyz="1.0 0.0 0.0"/>
    <parent link="torso_skin"/>
    <child link="torso_sensor_4"/>
  </joint>
  <link name="torso_sensor_4">
  </link>
  <joint name="torso_sensor_5_joint" type="fixed">
    <origin rpy="0.0 -0.0 -3.141592502593994" xyz="0.005103851668536663 -0.08538102358579636 0.48500001430511475"/>
    <axis xyz="0.0 0.0 1.0"/>
    <parent link="torso_skin"/>
    <child link="torso_sensor_5"/>
  </joint>
  <link name="torso_sensor_5">
  </link>
  <joint name="torso_sensor_6_joint" type="fixed">
    <origin rpy="1.5695937871932983 5.956879434165785e-08 -1.5707963705062866" xyz="-0.08294111490249634 0.056274738162755966 0.37553107738494873"/>
    <axis xyz="-0.9999992847442627 0.0 0.0012025213800370693"/>
    <parent link="torso_skin"/>
    <child link="torso_sensor_6"/>
  </joint>
  <link name="torso_sensor_6">
  </link>
  <joint name="torso_sensor_7_joint" type="fixed">
    <origin rpy="1.5695981979370117 -8.938909701328157e-08 1.5707964897155762" xyz="0.08299002796411514 -0.03272048383951187 0.33441245555877686"/>
    <axis xyz="0.9999992847442627 0.0 0.0011982430005446076"/>
    <parent link="torso_skin"/>
    <child link="torso_sensor_7"/>
  </joint>
  <link name="torso_sensor_7">
  </link>
  <joint name="torso_sensor_8_joint" type="fixed">
    <origin rpy="1.5707963705062866 -0.0 -1.5707963705062866" xyz="-0.08299999684095383 -0.01887003518640995 0.2242424637079239"/>
    <axis xyz="-1.0 0.0 0.0"/>
    <parent link="torso_skin"/>
    <child link="torso_sensor_8"/>
  </joint>
  <link name="torso_sensor_8">
  </link>
  <joint name="torso_sensor_9_joint" type="fixed">
    <origin rpy="1.5695937871932983 5.956879434165785e-08 -1.5707963705062866" xyz="-0.08288700878620148 -0.022590044885873795 0.42053765058517456"/>
    <axis xyz="-0.9999992847442627 0.0 0.0012025251053273678"/>
    <parent link="torso_skin"/>
    <child link="torso_sensor_9"/>
  </joint>
  <link name="torso_sensor_9">
  </link>
  <joint name="torso_sensor_10_joint" type="fixed">
    <origin rpy="1.5707963705062866 -0.0 1.5707963705062866" xyz="0.08299999684095383 0.05223296955227852 0.29285499453544617"/>
    <axis xyz="1.0 0.0 0.0"/>
    <parent link="torso_skin"/>
    <child link="torso_sensor_10"/>
  </joint>
  <link name="torso_sensor_10">
  </link>
  <!-- [m] -->
  <link name="head_skin">
    <visual>
      <origin rpy="0 0 0" xyz="0 0 0"/>
      <geometry>
        <mesh filename="meshes/skin/head_skin.stl" scale="1 1 1"/>
      </geometry>
    </visual>
  </link>
  <joint name="head_base_joint" type="fixed">
    <origin rpy="0 0 0" xyz="0 0 0"/>
    <parent link="torso_link"/>
    <child link="head_skin"/>
  </joint>
  <joint name="head_sensor_0_joint" type="fixed">
    <origin rpy="0.16059716045856476 6.478084202399259e-08 2.1646533012390137" xyz="0.05583661049604416 0.008467583917081356 0.7676398158073425"/>
    <axis xyz="0.13252970576286316 0.0894782543182373 0.9871319532394409"/>
    <parent link="head_skin"/>
    <child link="head_sensor_0"/>
  </joint>
  <link name="head_sensor_0">
  </link>
  <joint name="head_sensor_1_joint" type="fixed">
    <origin rpy="0.9451944231987 3.799994274800156e-08 1.5878266096115112" xyz="0.11821410804986954 0.002337978919968009 0.7354028224945068"/>
    <axis xyz="0.8104933500289917 0.013804281130433083 0.5855852961540222"/>
    <parent link="head_skin"/>
    <child link="head_sensor_1"/>
  </joint>
  <link name="head_sensor_1">
  </link>
  <joint name="head_sensor_2_joint" type="fixed">
    <origin rpy="0.41360539197921753 1.9830769915074598e-08 -0.23660646378993988" xyz="0.03686485439538956 -0.0376160703599453 0.7619104385375977"/>
    <axis xyz="-0.09421049803495407 -0.39071568846702576 0.9156776666641235"/>
    <parent link="head_skin"/>
    <child link="head_sensor_2"/>
  </joint>
  <link name="head_sensor_2">
  </link>
  <joint name="head_sensor_3_joint" type="fixed">
    <origin rpy="0.467112272977829 6.36125392361464e-08 -2.0584781169891357" xyz="0.003992740530520678 0.01790190301835537 0.7602173686027527"/>
    <axis xyz="-0.3978133201599121 0.2110057920217514 0.8928723931312561"/>
    <parent link="head_skin"/>
    <child link="head_sensor_3"/>
  </joint>
  <link name="head_sensor_3">
  </link>
  <joint name="head_sensor_4_joint" type="fixed">
    <origin rpy="0.5691347718238831 7.103718502321499e-09 0.8677659630775452" xyz="0.08610506355762482 -0.0333978608250618 0.7534815669059753"/>
    <axis xyz="0.4111221730709076 -0.34841856360435486 0.8423675298690796"/>
    <parent link="head_skin"/>
    <child link="head_sensor_4"/>
  </joint>
  <link name="head_sensor_4">
  </link>
  <joint name="head_sensor_5_joint" type="fixed">
    <origin rpy="0.9192641377449036 -3.6387891810818473e-08 2.9549601078033447" xyz="0.05854345113039017 0.06659458577632904 0.7398878931999207"/>
    <axis xyz="0.14754192531108856 0.7813473343849182 0.6064055562019348"/>
    <parent link="head_skin"/>
    <child link="head_sensor_5"/>
  </joint>
  <link name="head_sensor_5">
  </link>
  <!-- L arm -->
  <link name="left_shoulder_pitch_link">
    <inertial>
      <origin rpy="0 0 0" xyz="0.003053 0.06042 -0.0059"/>
      <mass value="1.327"/>
      <inertia ixx="0.00058661" ixy="-2.0157E-05" ixz="2.985E-06" iyy="0.0003989" iyz="2.238E-05" izz="0.00052936"/>
    </inertial>
    <visual>
      <origin rpy="0 0 0" xyz="0 0 0"/>
      <geometry>
        <mesh filename="meshes/left_shoulder_pitch_link.STL"/>
      </geometry>
      <material>
        <color rgba="0.1 0.1 0.1 1"/>
      </material>
    </visual>
    <collision>
      <origin rpy="0 0 0" xyz="0 0 0"/>
      <geometry>
        <mesh filename="meshes/left_shoulder_pitch_link.STL"/>
      </geometry>
    </collision>
  </link>
  <joint name="left_shoulder_pitch_joint" type="revolute">
    <origin rpy="0.2618 0 0" xyz="0 0.14806 0.42333"/>
    <parent link="torso_link"/>
    <child link="left_shoulder_pitch_link"/>
    <axis xyz="0 1 0"/>
    <limit effort="40" lower="-3.14" upper="1.57" velocity="9"/>
  </joint>
  <link name="left_shoulder_roll_link">
    <inertial>
      <origin rpy="0 0 0" xyz="-0.030932 -1E-06 -0.10609"/>
      <mass value="1.393"/>
      <inertia ixx="0.0018408" ixy="3.98E-07" ixz="-0.00048324" iyy="0.001934638" iyz="1.61E-07" izz="0.000617733"/>
    </inertial>
    <visual>
      <origin rpy="0 0 0" xyz="0 0 0"/>
      <geometry>
        <mesh filename="meshes/left_shoulder_roll_link.STL"/>
      </geometry>
      <material>
        <color rgba="0.1 0.1 0.1 1"/>
      </material>
    </visual>
    <collision>
      <origin rpy="0 0 0" xyz="0 0 0"/>
      <geometry>
        <mesh filename="meshes/left_shoulder_roll_link.STL"/>
      </geometry>
    </collision>
  </link>
  <joint name="left_shoulder_roll_joint" type="revolute">
    <origin rpy="-0.2618 0 0" xyz="0.0342 0.061999 -0.0060011"/>
    <parent link="left_shoulder_pitch_link"/>
    <child link="left_shoulder_roll_link"/>
    <axis xyz="1 0 0"/>
    <limit effort="40" lower="-0.38" upper="3.4" velocity="9"/>
  </joint>
  <!-- [m] -->
  <link name="left_shoulder_roll_skin">
    <visual>
      <origin rpy="0 0 0" xyz="0 0 0"/>
      <geometry>
        <mesh filename="meshes/skin/shoulder_roll_L_skin.stl" scale="1 1 1"/>
      </geometry>
    </visual>
  </link>
  <joint name="left_shoulder_roll_base_joint" type="fixed">
    <origin rpy="0.0 0 0" xyz="0 0 0"/>
    <parent link="left_shoulder_roll_link"/>
    <child link="left_shoulder_roll_skin"/>
  </joint>
  <joint name="left_shoulder_roll_sensor_0_joint" type="fixed">
    <origin rpy="1.551899790763855 -4.484040871943762e-08 1.563773512840271" xyz="0.021975861862301826 -0.0021392295602709055 0.005330793093889952"/>
    <axis xyz="0.9997968077659607 -0.007021559402346611 0.018895627930760384"/>
    <parent link="left_shoulder_roll_skin"/>
    <child link="left_shoulder_roll_sensor_0"/>
  </joint>
  <link name="left_shoulder_roll_sensor_0">
  </link>
  <joint name="left_shoulder_roll_sensor_1_joint" type="fixed">
    <origin rpy="1.570482611656189 5.187961704677946e-08 1.9563831090927124" xyz="0.017285505309700966 0.021028343588113785 -0.09356498718261719"/>
    <axis xyz="0.9265779256820679 0.37610265612602234 0.0003138364991173148"/>
    <parent link="left_shoulder_roll_skin"/>
    <child link="left_shoulder_roll_sensor_1"/>
  </joint>
  <link name="left_shoulder_roll_sensor_1">
  </link>
  <joint name="left_shoulder_roll_sensor_2_joint" type="fixed">
    <origin rpy="1.6504273414611816 -8.728313360961693e-08 1.9038336277008057" xyz="0.018528997898101807 0.021264299750328064 -0.05174817889928818"/>
    <axis xyz="0.9420590400695801 0.3258788585662842 -0.07954674959182739"/>
    <parent link="left_shoulder_roll_skin"/>
    <child link="left_shoulder_roll_sensor_2"/>
  </joint>
  <link name="left_shoulder_roll_sensor_2">
  </link>
  <joint name="left_shoulder_roll_sensor_3_joint" type="fixed">
    <origin rpy="1.5730558633804321 2.0718655235896222e-08 1.2191780805587769" xyz="0.017716117203235626 -0.019416000694036484 -0.09579524397850037"/>
    <axis xyz="0.9388141632080078 -0.3444167375564575 -0.002259491477161646"/>
    <parent link="left_shoulder_roll_skin"/>
    <child link="left_shoulder_roll_sensor_3"/>
  </joint>
  <link name="left_shoulder_roll_sensor_3">
  </link>
  <joint name="left_shoulder_roll_sensor_4_joint" type="fixed">
    <origin rpy="1.6502885818481445 -9.019574775948058e-08 0.8743812441825867" xyz="0.00962911918759346 -0.035556647926568985 -0.057738468050956726"/>
    <axis xyz="0.7647241353988647 -0.6394460201263428 -0.07940851151943207"/>
    <parent link="left_shoulder_roll_skin"/>
    <child link="left_shoulder_roll_sensor_4"/>
  </joint>
  <link name="left_shoulder_roll_sensor_4">
  </link>
  <joint name="left_shoulder_roll_sensor_5_joint" type="fixed">
    <origin rpy="1.6525324583053589 1.9534674322585488e-08 -2.9889297485351562" xyz="-0.042358122766017914 0.05419747531414032 -0.12676522135734558"/>
    <axis xyz="-0.1515629142522812 0.9850699305534363 -0.08164525777101517"/>
    <parent link="left_shoulder_roll_skin"/>
    <child link="left_shoulder_roll_sensor_5"/>
  </joint>
  <link name="left_shoulder_roll_sensor_5">
  </link>
  <joint name="left_shoulder_roll_sensor_6_joint" type="fixed">
    <origin rpy="1.6169135570526123 -2.047060831955605e-08 0.4328043460845947" xyz="-0.011077336966991425 -0.05010441690683365 -0.12087845802307129"/>
    <axis xyz="0.4189722537994385 -0.906827986240387 -0.04610069841146469"/>
    <parent link="left_shoulder_roll_skin"/>
    <child link="left_shoulder_roll_sensor_6"/>
  </joint>
  <link name="left_shoulder_roll_sensor_6">
  </link>
  <link name="left_shoulder_yaw_link">
    <inertial>
      <origin rpy="0 0 0" xyz="0.004583 0.001128 -0.001128"/>
      <mass value="1.505"/>
      <inertia ixx="0.004199" ixy="-1.7786E-05" ixz="0.00018372" iyy="0.0043139" iyz="9.278E-05" izz="0.00065755"/>
    </inertial>
    <visual>
      <origin rpy="0 0 0" xyz="0 0 0"/>
      <geometry>
        <mesh filename="meshes/left_shoulder_yaw_link.STL"/>
      </geometry>
      <material>
        <color rgba="0.1 0.1 0.1 1"/>
      </material>
    </visual>
    <collision>
      <origin rpy="0 0 0" xyz="0 0 0"/>
      <geometry>
        <mesh filename="meshes/left_shoulder_yaw_link.STL"/>
      </geometry>
    </collision>
  </link>
  <joint name="left_shoulder_yaw_joint" type="revolute">
    <origin rpy="0 0 0" xyz="-0.0342 0 -0.1456"/>
    <parent link="left_shoulder_roll_link"/>
    <child link="left_shoulder_yaw_link"/>
    <axis xyz="0 0 1"/>
    <limit effort="18" lower="-2.66" upper="3.01" velocity="20"/>
  </joint>
  <!-- [m] -->
  <link name="left_shoulder_yaw_skin">
    <visual>
      <origin rpy="0 0 0" xyz="0 0 0"/>
      <geometry>
        <mesh filename="meshes/skin/shoulder_yaw_L_skin.stl" scale="1 1 1"/>
      </geometry>
    </visual>
  </link>
  <joint name="left_shoulder_yaw_base_joint" type="fixed">
    <origin rpy="0 0 0" xyz="0 0 0"/>
    <parent link="left_shoulder_yaw_link"/>
    <child link="left_shoulder_yaw_skin"/>
  </joint>
  <joint name="left_shoulder_yaw_sensor_0_joint" type="fixed">
    <origin rpy="1.85941743850708 -4.787436225228703e-08 1.6624724864959717" xyz="0.041529230773448944 0.003520205384120345 -0.08673007041215897"/>
    <axis xyz="0.9546116590499878 0.08776101469993591 -0.2846307158470154"/>
    <parent link="left_shoulder_yaw_skin"/>
    <child link="left_shoulder_yaw_sensor_0"/>
  </joint>
  <link name="left_shoulder_yaw_sensor_0">
  </link>
  <joint name="left_shoulder_yaw_sensor_1_joint" type="fixed">
    <origin rpy="1.6501473188400269 6.971942667632902e-08 -2.3925929069519043" xyz="-0.035132333636283875 0.03415091335773468 -0.04077912122011185"/>
    <axis xyz="-0.6787640452384949 0.7300658226013184 -0.07926768064498901"/>
    <parent link="left_shoulder_yaw_skin"/>
    <child link="left_shoulder_yaw_sensor_1"/>
  </joint>
  <link name="left_shoulder_yaw_sensor_1">
  </link>
  <joint name="left_shoulder_yaw_sensor_2_joint" type="fixed">
    <origin rpy="1.5714919567108154 1.3637459517212847e-07 -1.7107082605361938" xyz="-0.04940275847911835 0.004836997017264366 -0.07897341996431351"/>
    <axis xyz="-0.9902281165122986 0.13945573568344116 -0.0006956477300263941"/>
    <parent link="left_shoulder_yaw_skin"/>
    <child link="left_shoulder_yaw_sensor_2"/>
  </joint>
  <link name="left_shoulder_yaw_sensor_2">
  </link>
  <joint name="left_shoulder_yaw_sensor_3_joint" type="fixed">
    <origin rpy="-1.2920538187026978 -3.1415927410125732 -0.03512994945049286" xyz="0.005767298396676779 0.03839176893234253 -0.07237497717142105"/>
    <axis xyz="0.033767059445381165 0.9608089327812195 -0.2751469612121582"/>
    <parent link="left_shoulder_yaw_skin"/>
    <child link="left_shoulder_yaw_sensor_3"/>
  </joint>
  <link name="left_shoulder_yaw_sensor_3">
  </link>
  <joint name="left_shoulder_yaw_sensor_4_joint" type="fixed">
    <origin rpy="1.5131322145462036 -1.965817375548795e-08 -0.492697536945343" xyz="-0.02568146213889122 -0.0444842129945755 -0.041484661400318146"/>
    <axis xyz="-0.47221818566322327 -0.8795956969261169 0.05763210728764534"/>
    <parent link="left_shoulder_yaw_skin"/>
    <child link="left_shoulder_yaw_sensor_4"/>
  </joint>
  <link name="left_shoulder_yaw_sensor_4">
  </link>
  <joint name="left_shoulder_yaw_sensor_5_joint" type="fixed">
    <origin rpy="1.594484806060791 -3.9004454777114006e-08 -3.01204776763916" xyz="-0.02670200914144516 0.027768440544605255 -0.11980567127466202"/>
    <axis xyz="-0.1291467845439911 0.9913425445556641 -0.023686012253165245"/>
    <parent link="left_shoulder_yaw_skin"/>
    <child link="left_shoulder_yaw_sensor_5"/>
  </joint>
  <link name="left_shoulder_yaw_sensor_5">
  </link>
  <link name="left_elbow_link">
    <inertial>
      <origin rpy="0 0 0" xyz="0.077092 -0.028751 -0.009714 "/>
      <mass value="0.691"/>
      <inertia ixx="0.000318491" ixy="0.000224554" ixz="6.62076E-05" iyy="0.000861224" iyz="-2.3329E-05" izz="0.000897899"/>
    </inertial>
    <visual>
      <origin rpy="0 0 0" xyz="0 0 0"/>
      <geometry>
        <mesh filename="meshes/left_elbow_link.STL"/>
      </geometry>
      <material>
        <color rgba="0.1 0.1 0.1 1"/>
      </material>
    </visual>
    <collision>
      <origin rpy="0 0 0" xyz="0 0 0"/>
      <geometry>
        <mesh filename="meshes/left_elbow_link.STL"/>
      </geometry>
    </collision>
  </link>
  <joint name="left_elbow_joint" type="revolute">
    <origin rpy="0 0 0" xyz="0.006 0.0329 -0.182"/>
    <parent link="left_shoulder_yaw_link"/>
    <child link="left_elbow_link"/>
    <axis xyz="0 1 0"/>
    <limit effort="18" lower="-0.95" upper="3.18" velocity="20"/>
  </joint>
  <!-- [m] -->
  <link name="left_elbow_skin">
    <visual>
      <origin rpy="0 0 0" xyz="0 0 0"/>
      <geometry>
        <mesh filename="meshes/skin/elbow_L_skin.stl" scale="1 1 1"/>
      </geometry>
    </visual>
  </link>
  <joint name="left_elbow_base_joint" type="fixed">
    <origin rpy="0 0 0" xyz="0 0 0"/>
    <parent link="left_elbow_link"/>
    <child link="left_elbow_skin"/>
  </joint>
  <joint name="left_elbow_sensor_0_joint" type="fixed">
    <origin rpy="1.2178651094436646 1.2016704964423752e-08 3.029371976852417" xyz="0.08154594898223877 0.008091652765870094 0.0070435362868011"/>
    <axis xyz="0.10508289933204651 0.932461142539978 0.34564992785453796"/>
    <parent link="left_elbow_skin"/>
    <child link="left_elbow_sensor_0"/>
  </joint>
  <link name="left_elbow_sensor_0">
  </link>
  <joint name="left_elbow_sensor_1_joint" type="fixed">
    <origin rpy="-1.1586705446243286 -3.141592502593994 -0.14596709609031677" xyz="0.03382901847362518 0.012922026216983795 -0.037048935890197754"/>
    <axis xyz="0.1332709938287735 0.9065275192260742 -0.4005580246448517"/>
    <parent link="left_elbow_skin"/>
    <child link="left_elbow_sensor_1"/>
  </joint>
  <link name="left_elbow_sensor_1">
  </link>
  <joint name="left_elbow_sensor_2_joint" type="fixed">
    <origin rpy="-1.063114881515503 -3.141592502593994 -0.17036668956279755" xyz="0.06889647245407104 0.006562706083059311 -0.03566919267177582"/>
    <axis xyz="0.14815989136695862 0.8612227439880371 -0.4861522316932678"/>
    <parent link="left_elbow_skin"/>
    <child link="left_elbow_sensor_2"/>
  </joint>
  <link name="left_elbow_sensor_2">
  </link>
  <joint name="left_elbow_sensor_3_joint" type="fixed">
    <origin rpy="2.8553733825683594 3.4038366569788536e-10 0.0035406488459557295" xyz="0.08601070940494537 -0.044811271131038666 -0.05210724472999573"/>
    <axis xyz="0.000999619485810399 -0.28232553601264954 -0.9593181014060974"/>
    <parent link="left_elbow_skin"/>
    <child link="left_elbow_sensor_3"/>
  </joint>
  <link name="left_elbow_sensor_3">
  </link>
  <joint name="left_elbow_sensor_4_joint" type="fixed">
    <origin rpy="1.1170960664749146 8.192893119485234e-08 2.7686517238616943" xyz="0.041937582194805145 0.01046033576130867 0.024017266929149628"/>
    <axis xyz="0.3274943232536316 0.8370455503463745 0.4382946193218231"/>
    <parent link="left_elbow_skin"/>
    <child link="left_elbow_sensor_4"/>
  </joint>
  <link name="left_elbow_sensor_4">
  </link>
  <joint name="left_elbow_sensor_5_joint" type="fixed">
    <origin rpy="1.570655345916748 -1.6653562084911755e-08 3.101487398147583" xyz="0.021635523065924644 0.01642613485455513 0.00085951026994735"/>
    <axis xyz="0.040094517171382904 0.99919593334198 0.00014104926958680153"/>
    <parent link="left_elbow_skin"/>
    <child link="left_elbow_sensor_5"/>
  </joint>
  <link name="left_elbow_sensor_5">
  </link>
  <joint name="left_elbow_sensor_6_joint" type="fixed">
    <origin rpy="1.571099042892456 -1.5052036062002117e-08 3.13824725151062" xyz="-0.007533484138548374 0.0170928705483675 -0.010090745985507965"/>
    <axis xyz="0.003345410106703639 0.9999943375587463 -0.0003027388593181968"/>
    <parent link="left_elbow_skin"/>
    <child link="left_elbow_sensor_6"/>
  </joint>
  <link name="left_elbow_sensor_6">
  </link>
  <joint name="left_elbow_sensor_7_joint" type="fixed">
    <origin rpy="-0.39322516322135925 -3.1415927410125732 -0.160541832447052" xyz="0.08704763650894165 -0.014367843046784401 -0.05096221715211868"/>
    <axis xyz="0.06125080958008766 0.37824228405952454 -0.9236780405044556"/>
    <parent link="left_elbow_skin"/>
    <child link="left_elbow_sensor_7"/>
  </joint>
  <link name="left_elbow_sensor_7">
  </link>
  <joint name="left_elbow_sensor_8_joint" type="fixed">
    <origin rpy="0.10821068286895752 -5.978086470292965e-09 0.09271365404129028" xyz="0.08814304322004318 -0.03759463131427765 0.031867414712905884"/>
    <axis xyz="0.009998704306781292 -0.10753583163022995 0.9941509366035461"/>
    <parent link="left_elbow_skin"/>
    <child link="left_elbow_sensor_8"/>
  </joint>
  <link name="left_elbow_sensor_8">
  </link>
  <joint name="left_elbow_sensor_9_joint" type="fixed">
    <origin rpy="1.571230411529541 1.0519261905983512e-07 3.006434440612793" xyz="0.051280681043863297 0.013466577976942062 -0.010949196293950081"/>
    <axis xyz="0.1347469836473465 0.9908799529075623 -0.00043415927211754024"/>
    <parent link="left_elbow_skin"/>
    <child link="left_elbow_sensor_9"/>
  </joint>
  <link name="left_elbow_sensor_9">
  </link>
  <joint name="left_elbow_sensor_10_joint" type="fixed">
    <origin rpy="1.3567856550216675 8.37537594833293e-09 -3.12361741065979" xyz="-0.00305706518702209 0.01633271388709545 0.03314973786473274"/>
    <axis xyz="-0.017564237117767334 0.9770290851593018 0.21238082647323608"/>
    <parent link="left_elbow_skin"/>
    <child link="left_elbow_sensor_10"/>
  </joint>
  <link name="left_elbow_sensor_10">
  </link>
  <link name="left_wrist_roll_link">
    <inertial>
      <origin rpy="0 0 0" xyz="0.035281 -0.002320 0.000337"/>
      <mass value="0.683"/>
      <inertia ixx="0.000313275" ixy="0.000016521" ixz="-0.000002501" iyy="0.000310412" iyz="0.000005435" izz="0.000345998"/>
    </inertial>
    <visual>
      <origin rpy="0 0 0" xyz="0 0 0"/>
      <geometry>
        <mesh filename="meshes/left_wrist_roll_link.STL"/>
      </geometry>
      <material>
        <color rgba="0.1 0.1 0.1 1"/>
      </material>
    </visual>
    <collision>
      <geometry>
        <mesh filename="meshes/left_wrist_roll_link.STL"/>
      </geometry>
    </collision>
  </link>
  <joint name="left_wrist_roll_joint" type="revolute">
    <origin rpy="0 0 0" xyz="0.121 -0.0329 -0.011"/>
    <parent link="left_elbow_link"/>
    <child link="left_wrist_roll_link"/>
    <axis xyz="1 0 0"/>
    <limit effort="19" lower="-3.01" upper="2.75" velocity="31.4"/>
  </joint>
  <link name="left_wrist_pitch_link">
    <inertial>
      <origin rpy="0 0 0" xyz="0.020395 0.000036 -0.002973"/>
      <mass value="0.484"/>
      <inertia ixx="0.000071364" ixy="0.000000308" ixz="0.000001485" iyy="0.000069915" iyz="-0.000000088" izz="0.000070702"/>
    </inertial>
    <visual>
      <origin rpy="0 0 0" xyz="0 0 0"/>
      <geometry>
        <mesh filename="meshes/left_wrist_pitch_link.STL"/>
      </geometry>
      <material>
        <color rgba="0.1 0.1 0.1 1"/>
      </material>
    </visual>
    <collision>
      <geometry>
        <mesh filename="meshes/left_wrist_pitch_link.STL"/>
      </geometry>
    </collision>
  </link>
  <joint name="left_wrist_pitch_joint" type="revolute">
    <origin rpy="0 0 0" xyz="0.087 0 0"/>
    <parent link="left_wrist_roll_link"/>
    <child link="left_wrist_pitch_link"/>
    <axis xyz="0 1 0"/>
    <limit effort="19" lower="-0.4625" upper="0.4625" velocity="31.4"/>
  </joint>
  <link name="left_wrist_yaw_link">
    <inertial>
      <origin rpy="0 0 0" xyz="0.027967 0.000096 0.000739"/>
      <mass value="0.124"/>
      <inertia ixx="137.3e-6" ixy="-0.171e-6" ixz="2.942e-6" iyy="169.998e-6" iyz="-0.025e-6" izz="84.808e-6"/>
    </inertial>
    <visual>
      <origin rpy="0 0 0" xyz="0 0 0"/>
      <geometry>
        <mesh filename="meshes/wrist_yaw_link.STL"/>
      </geometry>
      <material>
        <color rgba="0.1 0.1 0.1 1"/>
      </material>
    </visual>
    <!-- <collision>
      <origin xyz="0 0 0" rpy="0 0 0"/>
      <geometry>
        <mesh filename="${mesh_dir}/wrist_yaw_link.STL"/>
      </geometry>
    </collision> -->
  </link>
  <joint name="left_wrist_yaw_joint" type="revolute">
    <origin rpy="0 0 0" xyz="0.020 0 0"/>
    <parent link="left_wrist_pitch_link"/>
    <child link="left_wrist_yaw_link"/>
    <axis xyz="0 0 1"/>
    <limit effort="19" lower="-1.27" upper="1.27" velocity="31.4"/>
  </joint>
  <!-- R arm -->
  <link name="right_shoulder_pitch_link">
    <inertial>
      <origin rpy="0 0 0" xyz="0.003053 -0.06042 -0.0059"/>
      <mass value="1.327"/>
      <inertia ixx="0.00058661" ixy="2.0157E-05" ixz="2.985E-06" iyy="0.0003989" iyz="-2.238E-05" izz="0.00052936"/>
    </inertial>
    <visual>
      <origin rpy="0 0 0" xyz="0 0 0"/>
      <geometry>
        <mesh filename="meshes/right_shoulder_pitch_link.STL"/>
      </geometry>
      <material>
        <color rgba="0.1 0.1 0.1 1"/>
      </material>
    </visual>
    <collision>
      <origin rpy="0 0 0" xyz="0 0 0"/>
      <geometry>
        <mesh filename="meshes/right_shoulder_pitch_link.STL"/>
      </geometry>
    </collision>
  </link>
  <joint name="right_shoulder_pitch_joint" type="revolute">
    <origin rpy="-0.2618 0 0" xyz="0 -0.14806 0.42333"/>
    <parent link="torso_link"/>
    <child link="right_shoulder_pitch_link"/>
    <axis xyz="0 1 0"/>
    <limit effort="40" lower="-3.14" upper="1.57" velocity="9"/>
  </joint>
  <link name="right_shoulder_roll_link">
    <inertial>
      <origin rpy="0 0 0" xyz="-0.030932 1E-06 -0.10609"/>
      <mass value="1.393"/>
      <inertia ixx="0.0018408" ixy="-3.98E-07" ixz="-0.00048324" iyy="0.001934638" iyz="-1.61E-07" izz="0.000617733"/>
    </inertial>
    <visual>
      <origin rpy="0 0 0" xyz="0 0 0"/>
      <geometry>
        <mesh filename="meshes/right_shoulder_roll_link.STL"/>
      </geometry>
      <material>
        <color rgba="0.1 0.1 0.1 1"/>
      </material>
    </visual>
    <collision>
      <origin rpy="0 0 0" xyz="0 0 0"/>
      <geometry>
        <mesh filename="meshes/right_shoulder_roll_link.STL"/>
      </geometry>
    </collision>
  </link>
  <joint name="right_shoulder_roll_joint" type="revolute">
    <origin rpy="0.2618 0 0" xyz="0.0342 -0.061999 -0.0060011"/>
    <parent link="right_shoulder_pitch_link"/>
    <child link="right_shoulder_roll_link"/>
    <axis xyz="1 0 0"/>
    <limit effort="40" lower="-3.4" upper="0.38" velocity="9"/>
  </joint>
  <!-- [m] -->
  <link name="right_shoulder_roll_skin">
    <visual>
      <origin rpy="0 0 0" xyz="0 0 0"/>
      <geometry>
        <mesh filename="meshes/skin/shoulder_roll_R_skin.stl" scale="1 1 1"/>
      </geometry>
    </visual>
  </link>
  <joint name="right_shoulder_roll_base_joint" type="fixed">
    <origin rpy="0 0 0" xyz="0 0 0"/>
    <parent link="right_shoulder_roll_link"/>
    <child link="right_shoulder_roll_skin"/>
  </joint>
  <joint name="right_shoulder_roll_sensor_0_joint" type="fixed">
    <origin rpy="1.6110156774520874 -1.3015655042636354e-07 1.3825271129608154" xyz="0.02020913176238537 -0.010433539748191833 -0.1203891709446907"/>
    <axis xyz="0.9815351963043213 -0.18700765073299408 -0.04020834341645241"/>
    <parent link="right_shoulder_roll_skin"/>
    <child link="right_shoulder_roll_sensor_0"/>
  </joint>
  <link name="right_shoulder_roll_sensor_0">
  </link>
  <joint name="right_shoulder_roll_sensor_1_joint" type="fixed">
    <origin rpy="1.547227382659912 1.2260383641660155e-07 1.5840967893600464" xyz="0.02196035161614418 0.003525834996253252 0.006447893101722002"/>
    <axis xyz="0.9996338486671448 0.013296284712851048 0.023566756397485733"/>
    <parent link="right_shoulder_roll_skin"/>
    <child link="right_shoulder_roll_sensor_1"/>
  </joint>
  <link name="right_shoulder_roll_sensor_1">
  </link>
  <joint name="right_shoulder_roll_sensor_2_joint" type="fixed">
    <origin rpy="1.6198302507400513 3.5244884344365346e-08 1.4298112392425537" xyz="0.021171631291508675 -0.013482555747032166 -0.03812651336193085"/>
    <axis xyz="0.9888880252838135 -0.14034967124462128 -0.04901430755853653"/>
    <parent link="right_shoulder_roll_skin"/>
    <child link="right_shoulder_roll_sensor_2"/>
  </joint>
  <link name="right_shoulder_roll_sensor_2">
  </link>
  <joint name="right_shoulder_roll_sensor_3_joint" type="fixed">
    <origin rpy="1.5781761407852173 -1.408326113505609e-07 1.3229039907455444" xyz="0.019492628052830696 -0.013848518952727318 -0.07953478395938873"/>
    <axis xyz="0.9694053530693054 -0.24535463750362396 -0.007379625923931599"/>
    <parent link="right_shoulder_roll_skin"/>
    <child link="right_shoulder_roll_sensor_3"/>
  </joint>
  <link name="right_shoulder_roll_sensor_3">
  </link>
  <joint name="right_shoulder_roll_sensor_4_joint" type="fixed">
    <origin rpy="1.5731147527694702 -3.6292128413606406e-08 2.1917271614074707" xyz="0.011047429405152798 0.03214484453201294 -0.08381814509630203"/>
    <axis xyz="0.8133350610733032 0.5817909836769104 -0.002318537561222911"/>
    <parent link="right_shoulder_roll_skin"/>
    <child link="right_shoulder_roll_sensor_4"/>
  </joint>
  <link name="right_shoulder_roll_sensor_4">
  </link>
  <joint name="right_shoulder_roll_sensor_5_joint" type="fixed">
    <origin rpy="1.6344798803329468 4.719517221474234e-08 -1.7226282358169556" xyz="-0.0885578915476799 0.008191447705030441 -0.12311510741710663"/>
    <axis xyz="-0.9864919185638428 0.15094248950481415 -0.06364033371210098"/>
    <parent link="right_shoulder_roll_skin"/>
    <child link="right_shoulder_roll_sensor_5"/>
  </joint>
  <link name="right_shoulder_roll_sensor_5">
  </link>
  <joint name="right_shoulder_roll_sensor_6_joint" type="fixed">
    <origin rpy="1.6463441848754883 -1.1537085065072006e-08 -0.16923603415489197" xyz="-0.043252378702163696 -0.05412545055150986 -0.12589296698570251"/>
    <axis xyz="-0.1679488718509674 -0.9829021096229553 -0.07547598332166672"/>
    <parent link="right_shoulder_roll_skin"/>
    <child link="right_shoulder_roll_sensor_6"/>
  </joint>
  <link name="right_shoulder_roll_sensor_6">
  </link>
  <joint name="right_shoulder_roll_sensor_7_joint" type="fixed">
    <origin rpy="1.6160632371902466 -1.495763335412903e-08 2.7067909240722656" xyz="-0.010976525023579597 0.05005709081888199 -0.12077049911022186"/>
    <axis xyz="0.4207991361618042 0.9060245156288147 -0.04525141045451164"/>
    <parent link="right_shoulder_roll_skin"/>
    <child link="right_shoulder_roll_sensor_7"/>
  </joint>
  <link name="right_shoulder_roll_sensor_7">
  </link>
  <link name="right_shoulder_yaw_link">
    <inertial>
      <origin rpy="0 0 0" xyz="0.004583 -0.001128 -0.001128"/>
      <mass value="1.505"/>
      <inertia ixx="0.004199" ixy="1.7786E-05" ixz="0.00018372" iyy="0.0043139" iyz="-9.278E-05" izz="0.00065755"/>
    </inertial>
    <visual>
      <origin rpy="0 0 0" xyz="0 0 0"/>
      <geometry>
        <mesh filename="meshes/right_shoulder_yaw_link.STL"/>
      </geometry>
      <material>
        <color rgba="0.1 0.1 0.1 1"/>
      </material>
    </visual>
    <collision>
      <origin rpy="0 0 0" xyz="0 0 0"/>
      <geometry>
        <mesh filename="meshes/right_shoulder_yaw_link.STL"/>
      </geometry>
    </collision>
  </link>
  <joint name="right_shoulder_yaw_joint" type="revolute">
    <origin rpy="0 0 0" xyz="-0.0342 0 -0.1456"/>
    <parent link="right_shoulder_roll_link"/>
    <child link="right_shoulder_yaw_link"/>
    <axis xyz="0 0 1"/>
    <limit effort="18" lower="-3.01" upper="2.66" velocity="20"/>
  </joint>
  <!-- [m] -->
  <link name="right_shoulder_yaw_skin">
    <visual>
      <origin rpy="0 0 0" xyz="0 0 0"/>
      <geometry>
        <mesh filename="meshes/skin/shoulder_yaw_R_skin.stl" scale="1 1 1"/>
      </geometry>
    </visual>
  </link>
  <joint name="right_shoulder_yaw_base_joint" type="fixed">
    <origin rpy="0 0 0" xyz="0 0 0"/>
    <parent link="right_shoulder_yaw_link"/>
    <child link="right_shoulder_yaw_skin"/>
  </joint>
  <joint name="right_shoulder_yaw_sensor_0_joint" type="fixed">
    <origin rpy="1.8597503900527954 1.1286831025358879e-08 1.4440847635269165" xyz="0.04118751734495163 -0.004814512562006712 -0.08737954497337341"/>
    <axis xyz="0.9508576989173889 -0.12113388627767563 -0.28494971990585327"/>
    <parent link="right_shoulder_yaw_skin"/>
    <child link="right_shoulder_yaw_sensor_0"/>
  </joint>
  <link name="right_shoulder_yaw_sensor_0">
  </link>
  <joint name="right_shoulder_yaw_sensor_1_joint" type="fixed">
    <origin rpy="1.646294355392456 1.8119585831755103e-09 -0.7687416672706604" xyz="-0.035796575248241425 -0.03355425223708153 -0.04064032435417175"/>
    <axis xyz="-0.6932508945465088 -0.7167385220527649 -0.07542620599269867"/>
    <parent link="right_shoulder_yaw_skin"/>
    <child link="right_shoulder_yaw_sensor_1"/>
  </joint>
  <link name="right_shoulder_yaw_sensor_1">
  </link>
  <joint name="right_shoulder_yaw_sensor_2_joint" type="fixed">
    <origin rpy="1.8499118089675903 -2.4386073160798105e-09 0.04182104021310806" xyz="0.0068807341158390045 -0.038329385221004486 -0.07258914411067963"/>
    <axis xyz="0.04019082337617874 -0.9604589939117432 -0.2755054235458374"/>
    <parent link="right_shoulder_yaw_skin"/>
    <child link="right_shoulder_yaw_sensor_2"/>
  </joint>
  <link name="right_shoulder_yaw_sensor_2">
  </link>
  <joint name="right_shoulder_yaw_sensor_3_joint" type="fixed">
    <origin rpy="1.571201205253601 3.790614400145387e-08 -1.4650746583938599" xyz="-0.04953809827566147 -0.003564621554687619 -0.0796278566122055"/>
    <axis xyz="-0.9944165349006653 -0.10552489757537842 -0.0004047837865073234"/>
    <parent link="right_shoulder_yaw_skin"/>
    <child link="right_shoulder_yaw_sensor_3"/>
  </joint>
  <link name="right_shoulder_yaw_sensor_3">
  </link>
  <joint name="right_shoulder_yaw_sensor_4_joint" type="fixed">
    <origin rpy="1.5546531677246094 -2.4349319005523284e-08 -3.0059409141540527" xyz="-0.00878828577697277 0.04951019585132599 -0.0318453386425972"/>
    <axis xyz="-0.13521844148635864 0.9906842708587646 0.01614234782755375"/>
    <parent link="right_shoulder_yaw_skin"/>
    <child link="right_shoulder_yaw_sensor_4"/>
  </joint>
  <link name="right_shoulder_yaw_sensor_4">
  </link>
  <joint name="right_shoulder_yaw_sensor_5_joint" type="fixed">
    <origin rpy="1.5915374755859375 1.0039254760840777e-08 -0.16846124827861786" xyz="-0.0280979685485363 -0.027626603841781616 -0.11977264285087585"/>
    <axis xyz="-0.16762951016426086 -0.9856319427490234 -0.020739588886499405"/>
    <parent link="right_shoulder_yaw_skin"/>
    <child link="right_shoulder_yaw_sensor_5"/>
  </joint>
  <link name="right_shoulder_yaw_sensor_5">
  </link>
  <link name="right_elbow_link">
    <inertial>
      <origin rpy="0 0 0" xyz="0.077092 0.028751 -0.009714 "/>
      <mass value="0.691"/>
      <inertia ixx="0.000318491" ixy="-0.000224554" ixz="6.62076E-05" iyy="0.000861224" iyz="2.3329E-05" izz="0.000897899"/>
    </inertial>
    <visual>
      <origin rpy="0 0 0" xyz="0 0 0"/>
      <geometry>
        <mesh filename="meshes/right_elbow_link.STL"/>
      </geometry>
      <material>
        <color rgba="0.1 0.1 0.1 1"/>
      </material>
    </visual>
    <collision>
      <origin rpy="0 0 0" xyz="0 0 0"/>
      <geometry>
        <mesh filename="meshes/right_elbow_link.STL"/>
      </geometry>
    </collision>
  </link>
  <joint name="right_elbow_joint" type="revolute">
    <origin rpy="0 0 0" xyz="0.006 -0.0329 -0.182"/>
    <parent link="right_shoulder_yaw_link"/>
    <child link="right_elbow_link"/>
    <axis xyz="0 1 0"/>
    <limit effort="18" lower="-0.95" upper="3.18" velocity="20"/>
  </joint>
  <!-- [m] -->
  <link name="right_elbow_skin">
    <visual>
      <origin rpy="0 0 0" xyz="0 0 0"/>
      <geometry>
        <mesh filename="meshes/skin/elbow_R_skin.stl" scale="1 1 1"/>
      </geometry>
    </visual>
  </link>
  <joint name="right_elbow_base_joint" type="fixed">
    <origin rpy="0 0 0" xyz="0 0 0"/>
    <parent link="right_elbow_link"/>
    <child link="right_elbow_skin"/>
  </joint>
  <joint name="right_elbow_sensor_0_joint" type="fixed">
    <origin rpy="1.6108835935592651 3.0750507695742613e-10 -0.003349356586113572" xyz="-0.0054705264046788216 -0.01703549548983574 -0.02506975084543228"/>
    <axis xyz="-0.0033466597087681293 -0.9991910457611084 -0.04007663577795029"/>
    <parent link="right_elbow_skin"/>
    <child link="right_elbow_sensor_0"/>
  </joint>
  <link name="right_elbow_sensor_0">
  </link>
  <joint name="right_elbow_sensor_1_joint" type="fixed">
    <origin rpy="1.4375799894332886 -2.939074983387968e-09 0.032789308577775955" xyz="0.09776215255260468 -0.009773069061338902 -0.003952523693442345"/>
    <axis xyz="0.03249296545982361 -0.9906070828437805 0.1328226923942566"/>
    <parent link="right_elbow_skin"/>
    <child link="right_elbow_sensor_1"/>
  </joint>
  <link name="right_elbow_sensor_1">
  </link>
  <joint name="right_elbow_sensor_2_joint" type="fixed">
    <origin rpy="1.4639254808425903 -1.415918404745753e-08 0.13112856447696686" xyz="0.02981957234442234 -0.015662170946598053 0.0170421302318573"/>
    <axis xyz="0.13000711798667908 -0.9857586622238159 0.10666757822036743"/>
    <parent link="right_elbow_skin"/>
    <child link="right_elbow_sensor_2"/>
  </joint>
  <link name="right_elbow_sensor_2">
  </link>
  <joint name="right_elbow_sensor_3_joint" type="fixed">
    <origin rpy="2.034855842590332 1.6719945428178562e-09 0.1387859433889389" xyz="0.03183375298976898 -0.012470245361328125 -0.038558200001716614"/>
    <axis xyz="0.12371029704809189 -0.8856444358825684 -0.4475819766521454"/>
    <parent link="right_elbow_skin"/>
    <child link="right_elbow_sensor_3"/>
  </joint>
  <link name="right_elbow_sensor_3">
  </link>
  <joint name="right_elbow_sensor_4_joint" type="fixed">
    <origin rpy="0.5687653422355652 -1.8162769066520923e-08 0.12151739746332169" xyz="0.09520145505666733 0.008756054565310478 0.02564341574907303"/>
    <axis xyz="0.06528738886117935 -0.5346206426620483 0.8425664901733398"/>
    <parent link="right_elbow_skin"/>
    <child link="right_elbow_sensor_4"/>
  </joint>
  <link name="right_elbow_sensor_4">
  </link>
  <joint name="right_elbow_sensor_5_joint" type="fixed">
    <origin rpy="1.5707944631576538 2.0792034760575007e-10 0.004111796617507935" xyz="-0.006869952194392681 -0.017091382294893265 0.005429353564977646"/>
    <axis xyz="0.004111784510314465 -0.9999915361404419 2.02366391022224e-06"/>
    <parent link="right_elbow_skin"/>
    <child link="right_elbow_sensor_5"/>
  </joint>
  <link name="right_elbow_sensor_5">
  </link>
  <joint name="right_elbow_sensor_6_joint" type="fixed">
    <origin rpy="0.10568315535783768 -2.4437664336574016e-08 3.049027919769287" xyz="0.08788560330867767 0.03748124837875366 0.03188776969909668"/>
    <axis xyz="0.00975038856267929 0.10503476858139038 0.9944207668304443"/>
    <parent link="right_elbow_skin"/>
    <child link="right_elbow_sensor_6"/>
  </joint>
  <link name="right_elbow_sensor_6">
  </link>
  <joint name="right_elbow_sensor_7_joint" type="fixed">
    <origin rpy="2.8729567527770996 -1.6629815746682652e-08 0.188669815659523" xyz="0.08021856844425201 0.01752631552517414 -0.05247209593653679"/>
    <axis xyz="0.049779538065195084 -0.26070669293403625 -0.9641338586807251"/>
    <parent link="right_elbow_skin"/>
    <child link="right_elbow_sensor_7"/>
  </joint>
  <link name="right_elbow_sensor_7">
  </link>
  <joint name="right_elbow_sensor_8_joint" type="fixed">
    <origin rpy="2.093989372253418 -2.5215447507775934e-09 0.17718012630939484" xyz="0.06785736232995987 -0.006429128348827362 -0.03632089123129845"/>
    <axis xyz="0.15267664194107056 -0.8526670932769775 -0.4996485412120819"/>
    <parent link="right_elbow_skin"/>
    <child link="right_elbow_sensor_8"/>
  </joint>
  <link name="right_elbow_sensor_8">
  </link>
  <link name="right_wrist_roll_link">
    <inertial>
      <origin rpy="0 0 0" xyz="0.035281 -0.002320 0.000337"/>
      <mass value="0.683"/>
      <inertia ixx="0.000313275" ixy="0.000016521" ixz="-0.000002501" iyy="0.000310412" iyz="0.000005435" izz="0.000345998"/>
    </inertial>
    <visual>
      <origin rpy="0 0 0" xyz="0 0 0"/>
      <geometry>
        <mesh filename="meshes/right_wrist_roll_link.STL"/>
      </geometry>
      <material>
        <color rgba="0.1 0.1 0.1 1"/>
      </material>
    </visual>
    <collision>
      <geometry>
        <mesh filename="meshes/right_wrist_roll_link.STL"/>
      </geometry>
    </collision>
  </link>
  <joint name="right_wrist_roll_joint" type="revolute">
    <origin rpy="0 0 0" xyz="0.121 0.0329 -0.011"/>
    <parent link="right_elbow_link"/>
    <child link="right_wrist_roll_link"/>
    <axis xyz="1 0 0"/>
    <limit effort="19" lower="-2.75" upper="3.01" velocity="31.4"/>
  </joint>
  <link name="right_wrist_pitch_link">
    <inertial>
      <origin rpy="0 0 0" xyz="0.020395 0.000036 -0.002973"/>
      <mass value="0.484"/>
      <inertia ixx="0.000071364" ixy="0.000000308" ixz="0.000001485" iyy="0.000069915" iyz="-0.000000088" izz="0.000070702"/>
    </inertial>
    <visual>
      <origin rpy="0 0 0" xyz="0 0 0"/>
      <geometry>
        <mesh filename="meshes/right_wrist_pitch_link.STL"/>
      </geometry>
      <material>
        <color rgba="0.1 0.1 0.1 1"/>
      </material>
    </visual>
    <collision>
      <geometry>
        <mesh filename="meshes/right_wrist_pitch_link.STL"/>
      </geometry>
    </collision>
  </link>
  <joint name="right_wrist_pitch_joint" type="revolute">
    <origin rpy="0 0 0" xyz="0.087 0 0"/>
    <parent link="right_wrist_roll_link"/>
    <child link="right_wrist_pitch_link"/>
    <axis xyz="0 1 0"/>
    <limit effort="19" lower="-0.4625" upper="0.4625" velocity="31.4"/>
  </joint>
  <link name="right_wrist_yaw_link">
    <inertial>
      <origin rpy="0 0 0" xyz="0.027967 -0.000096 0.000739"/>
      <mass value="0.124"/>
      <inertia ixx="137.3e-6" ixy="0.171e-6" ixz="2.942e-6" iyy="169.998e-6" iyz="0.025e-6" izz="84.808e-6"/>
    </inertial>
    <visual>
      <origin rpy="0 0 0" xyz="0 0 0"/>
      <geometry>
        <mesh filename="meshes/wrist_yaw_link.STL"/>
      </geometry>
      <material>
        <color rgba="0.1 0.1 0.1 1"/>
      </material>
    </visual>
    <!-- <collision>
      <origin xyz="0 0 0" rpy="0 0 0"/>
      <geometry>
        <mesh filename="${mesh_dir}/wrist_yaw_link.STL"/>
      </geometry>
    </collision> -->
  </link>
  <joint name="right_wrist_yaw_joint" type="revolute">
    <origin rpy="0 0 0" xyz="0.020 0 0"/>
    <parent link="right_wrist_pitch_link"/>
    <child link="right_wrist_yaw_link"/>
    <axis xyz="0 0 1"/>
    <limit effort="19" lower="-1.27" upper="1.27" velocity="31.4"/>
  </joint>
  <!-- LOGO -->
  <link name="logo_link">
    <visual>
      <origin rpy="0 0 0" xyz="0 0 0"/>
      <geometry>
        <mesh filename="meshes/logo_link.STL"/>
      </geometry>
      <material>
        <color rgba="1 1 1 1"/>
      </material>
    </visual>
  </link>
  <joint name="logo_joint" type="fixed">
    <origin rpy="0 0 0" xyz="0 0 0"/>
    <parent link="torso_link"/>
    <child link="logo_link"/>
    <axis xyz="0 0 0"/>
  </joint>
  <!-- IMU -->
  <link name="imu_link"/>
  <joint name="imu_joint" type="fixed">
    <origin rpy="0 0 0" xyz="-0.04452 -0.01891 0.27756"/>
    <parent link="torso_link"/>
    <child link="imu_link"/>
  </joint>
  <!-- Camera&Lidar -->
  <link name="camera_link"/>
  <joint name="camera_joint" type="fixed">
    <origin rpy="0 0.8859291283123216 0" xyz="0.11109 0.01750 0.68789"/>
    <parent link="torso_link"/>
    <child link="camera_link"/>
  </joint>
  <link name="lidar_link"/>
  <joint name="lidar_joint" type="fixed">
    <origin rpy="0 0.24015730507441985 0" xyz="0.04874 0 0.67980"/>
    <parent link="torso_link"/>
    <child link="lidar_link"/>
  </joint>
</robot>
